Workbook
Name Count: Data_Validation!$N$2
Name Country: Salary_Calculator!$G$4
Name median_salary: Title!$I$2
Name median_salary_ex: Title!$G$2
Name Platform: Plataform!$G$2
Name Title: Salary_Calculator!$C$4
Name Type: Salary_Calculator!$K$4

Sheet Data
A1: job_title_short | B1: job_title | C1: job_location | D1: job_via | E1: job_schedule_type | F1: job_work_from_home | G1: search_location | H1: job_posted_date | I1: job_no_degree_mention | J1: job_health_insurance | K1: job_country | L1: salary_rate | M1: salary_year_avg | N1: salary_hour_avg | O1: company_name | P1: job_skills
A2: Data Analyst | B2: Data Analyst - Healthcare | C2: Brooklyn, NY | D2: Snagajob | E2: Full-time and Part-time | F2: FALSE | G2: New York, United States | H2: 45658 | I2: FALSE | J2: TRUE | K2: United States | L2: hour | N2: 27.98 | O2: Bedford Stuyvesant Family Health Center | P2: ['sql', 'excel', 'tableau', 'flow']
A3: Data Analyst | B3: Flight Test Engineer, Test Engineer, Test Data Analyst And Software Testing Position | C3: Patuxent River, MD | D3: Snagajob | E3: Full-time | F3: FALSE | G3: New York, United States | H3: 45658 | I3: TRUE | J3: FALSE | K3: United States | L3: hour | N3: 24.969999 | O3: Naval Air Systems Command (NAVAIR)
A4: Data Engineer | B4: Sr. Data Engineer Marketing & Campaign Management - Now Hiring | C4: Jersey City, NJ | D4: Snagajob | E4: Full-time and Part-time | F4: FALSE | G4: California, United States | H4: 45658.001 | I4: TRUE | J4: FALSE | K4: United States | L4: hour | N4: 54.420002 | O4: Inizio Partners | P4: ['sql', 'azure']
A5: Senior Data Analyst | B5: Sr Analyst, Healthcare Analytics - REMOTE | C5: Big Bend, WI | D5: Snagajob | E5: Full-time and Part-time | F5: FALSE | G5: Illinois, United States | H5: 45658.084 | I5: FALSE | J5: TRUE | K5: United States | L5: hour | N5: 44.799999 | O5: Molina Healthcare | P5: ['sql', 'crystal', 'databricks', 'excel', 'sharepoint']
A6: Senior Data Scientist | B6: Senior Data Scientist - Now Hiring | C6: Reading, PA | D6: Snagajob | E6: Full-time and Part-time | F6: FALSE | G6: New York, United States | H6: 45658.126 | I6: FALSE | J6: FALSE | K6: United States | L6: hour | N6: 33.709999 | O6: Penske | P6: ['python', 'sql', 'go', 'pyspark', 'docker', 'kubernetes']
A7: Senior Data Scientist | B7: Senior Data Scientist - Now Hiring | C7: Reading, PA | D7: Snagajob | E7: Full-time and Part-time | F7: FALSE | G7: New York, United States | H7: 45658.126 | I7: FALSE | J7: FALSE | K7: United States | L7: hour | N7: 33.709999 | O7: Penske | P7: ['python', 'sql', 'go', 'pyspark', 'docker', 'kubernetes']
A8: Senior Data Analyst | B8: Senior Data Analyst / Manager | C8: New York, NY | D8: JobLeads | E8: Full-time | F8: FALSE | G8: New York, United States | H8: 45658.25 | I8: TRUE | J8: FALSE | K8: United States | L8: year | M8: 90000 | O8: Maimonides Medical Center | P8: ['excel', 'tableau']
A9: Data Scientist | B9: Data Scientist | C9: Abilene, TX | D9: Ladders | E9: Full-time | F9: FALSE | G9: Texas, United States | H9: 45658.251 | I9: FALSE | J9: TRUE | K9: United States | L9: year | M9: 97574 | O9: Warren CAT | P9: ['nosql', 'r', 'python', 'c', 'tableau']
A10: Data Scientist | B10: Lead Data Science Engineer | C10: New York, NY | D10: LinkedIn | E10: Full-time | F10: FALSE | G10: New York, United States | H10: 45658.251 | I10: FALSE | J10: TRUE | K10: United States | L10: year | M10: 157500 | O10: Arlo | P10: ['python', 'sql', 'watson', 'aws', 'pyspark', 'docker']
A11: Data Engineer | B11: Data Engineer / Developer | C11: Summit, NJ | D11: ZipRecruiter | E11: Full-time | F11: FALSE | G11: New York, United States | H11: 45658.251 | I11: FALSE | J11: TRUE | K11: United States | L11: year | M11: 120000 | O11: Simplicity Group Holdings | P11: ['python', 'sql', 'mysql', 'aws', 'azure', 'atlassian', 'bitbucket', 'jira', 'confluence']
A12: Data Engineer | B12: Data Engineer / Developer | C12: Summit, NJ | D12: ZipRecruiter | E12: Full-time | F12: FALSE | G12: New York, United States | H12: 45658.251 | I12: FALSE | J12: TRUE | K12: United States | L12: year | M12: 120000 | O12: Simplicity Group Holdings | P12: ['python', 'sql', 'mysql', 'aws', 'azure', 'atlassian', 'bitbucket', 'jira', 'confluence']
A13: Senior Data Engineer | B13: Senior Data Engineer | C13: Creve Coeur, MO | D13: JobzMall | E13: Full-time | F13: FALSE | G13: Illinois, United States | H13: 45658.266 | I13: FALSE | J13: FALSE | K13: United States | L13: year | M13: 128000 | O13: Bayer | P13: ['python', 'java', 'spark', 'hadoop']
A14: Senior Data Engineer | B14: Senior Data Engineer | C14: New York, NY | D14: Snagajob | E14: Full-time and Part-time | F14: FALSE | G14: Illinois, United States | H14: 45658.266 | I14: FALSE | J14: TRUE | K14: United States | L14: hour | N14: 54.420002 | O14: Capital One | P14: ['java', 'scala', 'python', 'nosql', 'sql', 'mongo', 'shell', 'mysql', 'cassandra', 'redshift', 'snowflake', 'aws', 'azure', 'hadoop', 'kafka', 'spark']
A15: Senior Data Engineer | B15: Senior Data Engineer | C15: New York, NY | D15: Snagajob | E15: Full-time and Part-time | F15: FALSE | G15: Illinois, United States | H15: 45658.266 | I15: FALSE | J15: TRUE | K15: United States | L15: hour | N15: 54.420002 | O15: Capital One | P15: ['java', 'scala', 'python', 'nosql', 'sql', 'mongo', 'shell', 'mysql', 'cassandra', 'redshift', 'snowflake', 'aws', 'azure', 'hadoop', 'kafka', 'spark']
A16: Data Engineer | B16: Data Engineer (TS/SCI + CI Poly) | C16: Melbourne, FL | D16: Ladders | E16: Full-time | F16: FALSE | G16: Florida, United States | H16: 45658.267 | I16: FALSE | J16: TRUE | K16: United States | L16: year | M16: 141420 | O16: The DarkStar Group, LLC | P16: ['java', 'python', 'c#', 'sql', 'nosql', 'mongodb', 'mongodb', 'kotlin', 'elasticsearch', 'neo4j', 'postgresql', 'mysql', 'openstack', 'aws', 'gcp', 'azure', 'hadoop', 'spark', 'airflow', 'linux', 'tableau', 'power bi', 'ansible', 'flow', 'docker', 'kubernetes']
A17: Data Engineer | B17: Lead Data Engineer | C17: New York, NY | D17: Snagajob | E17: Full-time and Part-time | F17: FALSE | G17: Florida, United States | H17: 45658.267 | I17: FALSE | J17: TRUE | K17: United States | L17: hour | N17: 54.420002 | O17: Capital One | P17: ['java', 'scala', 'python', 'nosql', 'sql', 'mongo', 'shell', 'mysql', 'cassandra', 'redshift', 'snowflake', 'aws', 'azure', 'hadoop', 'kafka', 'spark']
A18: Data Engineer | B18: Lead Data Engineer | C18: New York, NY | D18: Snagajob | E18: Full-time and Part-time | F18: FALSE | G18: Florida, United States | H18: 45658.267 | I18: FALSE | J18: TRUE | K18: United States | L18: hour | N18: 54.420002 | O18: Capital One | P18: ['java', 'scala', 'python', 'nosql', 'sql', 'mongo', 'shell', 'mysql', 'cassandra', 'redshift', 'snowflake', 'aws', 'azure', 'hadoop', 'kafka', 'spark']
A19: Data Analyst | B19: Data Analyst - Risk Management and Monitoring (Turkey) | C19: Anywhere | D19: Jobgether | E19: Full-time | F19: TRUE | G19: Turkey | H19: 45658.268 | I19: FALSE | J19: FALSE | K19: Turkey | L19: year | M19: 39480 | O19: Sezzle | P19: ['sql', 'python', 'sas', 'sas', 'postgresql', 'redshift', 'aws', 'tableau', 'looker', 'power bi']
A20: Data Analyst | B20: Data Analyst - Risk Management and Monitoring (Turkey) | C20: Anywhere | D20: Jobgether | E20: Full-time | F20: TRUE | G20: Turkey | H20: 45658.268 | I20: FALSE | J20: FALSE | K20: Turkey | L20: year | M20: 39480 | O20: Sezzle | P20: ['sql', 'python', 'sas', 'sas', 'postgresql', 'redshift', 'aws', 'tableau', 'looker', 'power bi']
A21: Data Scientist | B21: Sr Data Scientist - LLM | C21: Anywhere | D21: LinkedIn | E21: Contractor | F21: TRUE | G21: Macedonia (FYROM) | H21: 45658.269 | I21: FALSE | J21: FALSE | K21: Macedonia (FYROM) | L21: hour | N21: 19.5 | O21: YO IT CONSULTING | P21: ['python', 'jupyter', 'express']
A22: Senior Data Engineer | B22: Senior Data Engineer | C22: Anywhere | D22: Jobgether | E22: Full-time | F22: TRUE | G22: Bahrain | H22: 45658.269 | I22: TRUE | J22: FALSE | K22: Bahrain | L22: year | M22: 90000 | O22: Altimate AI | P22: ['sql', 'python', 'snowflake', 'aws', 'airflow', 'git', 'kubernetes', 'slack']
A23: Senior Data Engineer | B23: Senior Data Engineer | C23: Anywhere | D23: Jobgether | E23: Full-time | F23: TRUE | G23: Bahrain | H23: 45658.269 | I23: TRUE | J23: TRUE | K23: Bahrain | L23: year | M23: 192000 | O23: Docker | P23: ['c', 'python', 'sql', 'snowflake', 'bigquery', 'kafka', 'looker', 'tableau', 'docker']
A24: Data Scientist | B24: Data Scientist - LLM | C24: Anywhere | D24: LinkedIn | E24: Contractor | F24: TRUE | G24: Nepal | H24: 45658.269 | I24: FALSE | J24: FALSE | K24: Nepal | L24: hour | N24: 19.5 | O24: YO IT CONSULTING | P24: ['python', 'jupyter', 'express']
A25: Senior Data Engineer | B25: Senior Data Engineer (V) | C25: Anywhere | D25: Rise | E25: Full-time | F25: TRUE | G25: Dominican Republic | H25: 45658.27 | I25: FALSE | J25: FALSE | K25: Dominican Republic | L25: year | M25: 90000 | O25: Blue Coding | P25: ['python', 'scala', 'sql', 'nosql', 'redshift', 'spark', 'tableau', 'git', 'terraform', 'jira']
A26: Data Engineer | B26: Junior Data Engineer (V) | C26: Anywhere | D26: Rise | E26: Full-time | F26: TRUE | G26: Dominican Republic | H26: 45658.27 | I26: FALSE | J26: FALSE | K26: Dominican Republic | L26: year | M26: 75000 | O26: Blue Coding | P26: ['python', 'scala', 'sql', 'nosql', 'aws', 'spark', 'tableau', 'terraform']
A27: Data Scientist | B27: Sr Data Scientist - LLM | C27: Anywhere | D27: LinkedIn | E27: Contractor | F27: TRUE | G27: Algeria | H27: 45658.27 | I27: FALSE | J27: FALSE | K27: Algeria | L27: hour | N27: 19.5 | O27: YO IT CONSULTING | P27: ['python', 'jupyter', 'express']
A28: Data Scientist | B28: Data Scientist - LLM | C28: Anywhere | D28: LinkedIn | E28: Contractor | F28: TRUE | G28: Chile | H28: 45658.271 | I28: FALSE | J28: FALSE | K28: Chile | L28: hour | N28: 19.5 | O28: YO IT CONSULTING | P28: ['python', 'jupyter', 'express']
A29: Data Engineer | B29: Python Engineer (Data Integrations) | C29: Santiago, Chile | D29: Taro | E29: Full-time | F29: FALSE | G29: Chile | H29: 45658.271 | I29: TRUE | J29: FALSE | K29: Chile | L29: year | M29: 60000 | O29: AltScore | P29: ['python']
A30: Data Engineer | B30: Python Engineer (Data Integrations) | C30: Santiago, Chile | D30: Taro | E30: Full-time | F30: FALSE | G30: Chile | H30: 45658.271 | I30: TRUE | J30: FALSE | K30: Chile | L30: year | M30: 60000 | O30: AltScore | P30: ['python']
A31: Data Scientist | B31: Data Scientist - LLM | C31: Anywhere | D31: LinkedIn Tanzania | E31: Contractor | F31: TRUE | G31: Tanzania | H31: 45658.272 | I31: FALSE | J31: FALSE | K31: Tanzania | L31: hour | N31: 19.5 | O31: YO IT CONSULTING | P31: ['python', 'jupyter', 'express']
A32: Data Engineer | B32: Python Developer / Data Engineer | C32: Aguadilla, Puerto Rico | D32: Ladders | E32: Full-time | F32: FALSE | G32: Puerto Rico | H32: 45658.273 | I32: FALSE | J32: FALSE | K32: Puerto Rico | L32: year | M32: 80811 | O32: Grupo Oricteropo Tropical | P32: ['go', 'python', 'sql', 'pandas', 'linux', 'git']
A33: Senior Data Scientist | B33: Senior Data Scientist - Service Enablement Analytics | C33: Anywhere | D33: Jobgether | E33: Full-time | F33: TRUE | G33: Australia | H33: 45658.273 | I33: FALSE | J33: FALSE | K33: Australia | L33: year | M33: 189000 | O33: Atlassian | P33: ['css', 'sql', 'python', 'r', 'c', 'pandas', 'numpy', 'scikit-learn', 'tableau', 'atlassian']
A34: Data Engineer | B34: Data Engineer | C34: Durango, Mexico (+2 others) | D34: Built In | E34: Full-time | F34: FALSE | G34: Mexico | H34: 45658.273 | I34: FALSE | J34: TRUE | K34: Mexico | L34: year | M34: 143250 | O34: Abbott | P34: ['sql', 'python', 'scala', 'aws', 'azure', 'redshift', 'spark']
A35: Data Scientist | B35: Data Scientist - LLM | C35: Anywhere | D35: LinkedIn El Salvador | E35: Contractor | F35: TRUE | G35: El Salvador | H35: 45658.273 | I35: FALSE | J35: FALSE | K35: El Salvador | L35: hour | N35: 19.5 | O35: YO IT CONSULTING | P35: ['python', 'jupyter', 'express']
A36: Data Scientist | B36: Sr Data Scientist - LLM | C36: Anywhere | D36: LinkedIn Cameroon | E36: Contractor | F36: TRUE | G36: Cameroon | H36: 45658.274 | I36: FALSE | J36: FALSE | K36: Cameroon | L36: hour | N36: 19.5 | O36: YO IT CONSULTING | P36: ['python', 'jupyter', 'express']
A37: Data Scientist | B37: Sr Data Scientist - LLM | C37: Anywhere | D37: LinkedIn Slovakia | E37: Contractor | F37: TRUE | G37: Slovakia | H37: 45658.274 | I37: FALSE | J37: FALSE | K37: Slovakia | L37: hour | N37: 19.5 | O37: YO IT CONSULTING | P37: ['python', 'jupyter', 'express']
A38: Data Scientist | B38: Data Scientist - LLM | C38: Anywhere | D38: LinkedIn Kazakhstan | E38: Contractor | F38: TRUE | G38: Kazakhstan | H38: 45658.275 | I38: FALSE | J38: FALSE | K38: Kazakhstan | L38: hour | N38: 19.5 | O38: YO IT CONSULTING | P38: ['python', 'jupyter', 'express']
A39: Data Scientist | B39: Data Scientist - LLM | C39: Anywhere | D39: LinkedIn | E39: Contractor | F39: TRUE | G39: Venezuela | H39: 45658.275 | I39: FALSE | J39: FALSE | K39: Venezuela | L39: hour | N39: 19.5 | O39: YO IT CONSULTING | P39: ['python', 'jupyter', 'express']
A40: Data Analyst | B40: Product Data Analyst (Chile) | C40: Anywhere | D40: Built In | E40: Full-time | F40: TRUE | G40: Chile | H40: 45658.276 | I40: FALSE | J40: FALSE | K40: Chile | L40: year | M40: 37499.5 | O40: Sezzle | P40: ['sql', 'python', 'postgresql', 'redshift', 'aws', 'tableau', 'looker', 'power bi']
...

Sheet Salary_Calculator
B1: Data Science Salary Calculator
C3: Job Title: | G3: Country: | K3: Type:
C4: Data Analyst | G4: United States | K4: Full-time

Sheet Data_Validation
A1: job_title_short | B1: count | D1: job_title_short sorted | G1: job_country | H1: job_country_sorted | J1: job_schedule_type | K1: job_schedule_type_sorted
A2: {=_xlfn.UNIQUE(jobs[job_title_short])} -> Data Analyst | B2: {=COUNT( IF( (jobs[job_country]=Country)* (jobs[job_title_short]=A2)* (ISNUMBER(SEARCH(Type,jobs[job_schedule_type]))), jobs[salary_year_avg] ))} -> 3053 | D2: {=_xlfn._xlws.SORT(A2:B11,2,-1,)} -> Data Analyst | E2: 3053 | G2: {=_xlfn.UNIQUE(jobs[job_country])} -> United States | H2: {=_xlfn._xlws.SORT(_xlfn.ANCHORARRAY(G2))} -> 0 | J2: {=_xlfn.UNIQUE(jobs[job_schedule_type])} -> Full-time and Part-time | K2: {=_xlfn._xlws.FILTER(_xlfn.ANCHORARRAY(J2),NOT(ISNUMBER(SEARCH("and",_xlfn.ANCHORARRAY(J2))))*(_xlfn.ANCHORARRAY(J2)<>0))} -> Full-time | N2: =_xlfn.XLOOKUP(Title,D2:D11,E2:E11,"Not Found") -> 3053
A3: Data Engineer | B3: {=COUNT( IF( (jobs[job_country]=Country)* (jobs[job_title_short]=A3)* (ISNUMBER(SEARCH(Type,jobs[job_schedule_type]))), jobs[salary_year_avg] ))} -> 2740 | D3: Data Engineer | E3: 2740 | G3: Turkey | H3: Afghanistan | J3: Full-time | K3: Contractor
A4: Senior Data Analyst | B4: {=COUNT( IF( (jobs[job_country]=Country)* (jobs[job_title_short]=A4)* (ISNUMBER(SEARCH(Type,jobs[job_schedule_type]))), jobs[salary_year_avg] ))} -> 522 | D4: Data Scientist | E4: 1508 | G4: Macedonia (FYROM) | H4: Albania | J4: Contractor | K4: Part-time
A5: Senior Data Scientist | B5: {=COUNT( IF( (jobs[job_country]=Country)* (jobs[job_title_short]=A5)* (ISNUMBER(SEARCH(Type,jobs[job_schedule_type]))), jobs[salary_year_avg] ))} -> 493 | D5: Senior Data Engineer | E5: 783 | G5: Bahrain | H5: Algeria | J5: Part-time | K5: Internship
A6: Data Scientist | B6: {=COUNT( IF( (jobs[job_country]=Country)* (jobs[job_title_short]=A6)* (ISNUMBER(SEARCH(Type,jobs[job_schedule_type]))), jobs[salary_year_avg] ))} -> 1508 | D6: Senior Data Analyst | E6: 522 | G6: Nepal | H6: Argentina | J6: Internship
A7: Senior Data Engineer | B7: {=COUNT( IF( (jobs[job_country]=Country)* (jobs[job_title_short]=A7)* (ISNUMBER(SEARCH(Type,jobs[job_schedule_type]))), jobs[salary_year_avg] ))} -> 783 | D7: Business Analyst | E7: 510 | G7: Dominican Republic | H7: Armenia | J7: Full-time and Contractor
A8: Software Engineer | B8: {=COUNT( IF( (jobs[job_country]=Country)* (jobs[job_title_short]=A8)* (ISNUMBER(SEARCH(Type,jobs[job_schedule_type]))), jobs[salary_year_avg] ))} -> 364 | D8: Senior Data Scientist | E8: 493 | G8: Algeria | H8: Australia | J8: 0
A9: Machine Learning Engineer | B9: {=COUNT( IF( (jobs[job_country]=Country)* (jobs[job_title_short]=A9)* (ISNUMBER(SEARCH(Type,jobs[job_schedule_type]))), jobs[salary_year_avg] ))} -> 291 | D9: Software Engineer | E9: 364 | G9: Chile | H9: Austria | J9: Full-time and Internship
A10: Cloud Engineer | B10: {=COUNT( IF( (jobs[job_country]=Country)* (jobs[job_title_short]=A10)* (ISNUMBER(SEARCH(Type,jobs[job_schedule_type]))), jobs[salary_year_avg] ))} -> 67 | D10: Machine Learning Engineer | E10: 291 | G10: Tanzania | H10: Azerbaijan | J10: Full-time, Part-time, and Contractor
A11: Business Analyst | B11: {=COUNT( IF( (jobs[job_country]=Country)* (jobs[job_title_short]=A11)* (ISNUMBER(SEARCH(Type,jobs[job_schedule_type]))), jobs[salary_year_avg] ))} -> 510 | D11: Cloud Engineer | E11: 67 | G11: Puerto Rico | H11: Bahamas | J11: Part-time and Contractor
A12: 0 | G12: Australia | H12: Bahrain | J12: Part-time and Internship
G13: Mexico | H13: Bangladesh | J13: Full-time, Part-time, and Internship
G14: El Salvador | H14: Barbados
G15: Cameroon | H15: Belarus
G16: Slovakia | H16: Benin
G17: Kazakhstan | H17: Bolivia
G18: Venezuela | H18: Brazil
G19: Bolivia | H19: Brunei
G20: Cambodia | H20: Cambodia
G21: Oman | H21: Cameroon
G22: Kuwait | H22: Canada
G23: Sudan | H23: Cayman Islands
G24: Bahamas | H24: Chile
G25: Barbados | H25: Colombia
... G27: Guyana | H27: Costa Rica
G28: 0 | H28: Cyprus
G29: U.S. Virgin Islands | H29: Czechia
G30: Northern Mariana Islands | H30: Denmark
G31: Kenya | H31: Dominican Republic
G32: Indonesia | H32: Ecuador
G33: Serbia | H33: Egypt
G34: Sri Lanka | H34: El Salvador
G35: Pakistan | H35: Estonia
G36: Hungary | H36: Ethiopia
G37: Nicaragua | H37: Finland
G38: Montenegro | H38: France
G39: Guam | H39: Germany
G40: Lesotho | H40: Ghana
... G132: Luxembourg | H132: Zimbabwe

Sheet Title
A1: job_title_short
A2: {=Data_Validation!D2:D11} -> Data Analyst | B2: {=MEDIAN( IF( (jobs[job_title_short]=A2)* (jobs[salary_year_avg]<>0)* (jobs[job_country]= Country)* (ISNUMBER(SEARCH(Type,jobs[job_schedule_type]))), jobs[salary_year_avg] ) )} -> 93580 | D2: {=_xlfn._xlws.SORT(_xlfn._xlws.FILTER(A2:B11,ISNUMBER(B2:B11)),2,1)} -> Data Analyst | E2: 93580 | F2: =IF($D2<>Title,$E2,NA()) -> #N/A | G2: =IF($D2=Title,$E2,NA()) -> 93580 | I2: =_xlfn.XLOOKUP(Title,D2:D11,E2:E11,"Not Found") -> 93580
A3: Data Engineer | B3: {=MEDIAN( IF( (jobs[job_title_short]=A3)* (jobs[salary_year_avg]<>0)* (jobs[job_country]= Country)* (ISNUMBER(SEARCH(Type,jobs[job_schedule_type]))), jobs[salary_year_avg] ) )} -> 135000 | D3: Business Analyst | E3: 103900 | F3: =IF($D3<>Title,E3,NA()) -> 103900 | G3: =IF($D3=Title,$E3,NA()) -> #N/A
A4: Data Scientist | B4: {=MEDIAN( IF( (jobs[job_title_short]=A4)* (jobs[salary_year_avg]<>0)* (jobs[job_country]= Country)* (ISNUMBER(SEARCH(Type,jobs[job_schedule_type]))), jobs[salary_year_avg] ) )} -> 137500 | D4: Senior Data Analyst | E4: 116275 | F4: =IF($D4<>Title,E4,NA()) -> 116275 | G4: =IF($D4=Title,$E4,NA()) -> #N/A
A5: Senior Data Engineer | B5: {=MEDIAN( IF( (jobs[job_title_short]=A5)* (jobs[salary_year_avg]<>0)* (jobs[job_country]= Country)* (ISNUMBER(SEARCH(Type,jobs[job_schedule_type]))), jobs[salary_year_avg] ) )} -> 149743 | D5: Data Engineer | E5: 135000 | F5: =IF($D5<>Title,E5,NA()) -> 135000 | G5: =IF($D5=Title,$E5,NA()) -> #N/A
A6: Senior Data Analyst | B6: {=MEDIAN( IF( (jobs[job_title_short]=A6)* (jobs[salary_year_avg]<>0)* (jobs[job_country]= Country)* (ISNUMBER(SEARCH(Type,jobs[job_schedule_type]))), jobs[salary_year_avg] ) )} -> 116275 | D6: Cloud Engineer | E6: 137300 | F6: =IF($D6<>Title,E6,NA()) -> 137300 | G6: =IF($D6=Title,$E6,NA()) -> #N/A
A7: Business Analyst | B7: {=MEDIAN( IF( (jobs[job_title_short]=A7)* (jobs[salary_year_avg]<>0)* (jobs[job_country]= Country)* (ISNUMBER(SEARCH(Type,jobs[job_schedule_type]))), jobs[salary_year_avg] ) )} -> 103900 | D7: Data Scientist | E7: 137500 | F7: =IF($D7<>Title,E7,NA()) -> 137500 | G7: =IF($D7=Title,$E7,NA()) -> #N/A
A8: Senior Data Scientist | B8: {=MEDIAN( IF( (jobs[job_title_short]=A8)* (jobs[salary_year_avg]<>0)* (jobs[job_country]= Country)* (ISNUMBER(SEARCH(Type,jobs[job_schedule_type]))), jobs[salary_year_avg] ) )} -> 160992 | D8: Senior Data Engineer | E8: 149743 | F8: =IF($D8<>Title,E8,NA()) -> 149743 | G8: =IF($D8=Title,$E8,NA()) -> #N/A
A9: Software Engineer | B9: {=MEDIAN( IF( (jobs[job_title_short]=A9)* (jobs[salary_year_avg]<>0)* (jobs[job_country]= Country)* (ISNUMBER(SEARCH(Type,jobs[job_schedule_type]))), jobs[salary_year_avg] ) )} -> 160000 | D9: Machine Learning Engineer | E9: 157500 | F9: =IF($D9<>Title,E9,NA()) -> 157500 | G9: =IF($D9=Title,$E9,NA()) -> #N/A
A10: Machine Learning Engineer | B10: {=MEDIAN( IF( (jobs[job_title_short]=A10)* (jobs[salary_year_avg]<>0)* (jobs[job_country]= Country)* (ISNUMBER(SEARCH(Type,jobs[job_schedule_type]))), jobs[salary_year_avg] ) )} -> 157500 | D10: Software Engineer | E10: 160000 | F10: =IF($D10<>Title,E10,NA()) -> 160000 | G10: =IF($D10=Title,$E10,NA()) -> #N/A
A11: Cloud Engineer | B11: {=MEDIAN( IF( (jobs[job_title_short]=A11)* (jobs[salary_year_avg]<>0)* (jobs[job_country]= Country)* (ISNUMBER(SEARCH(Type,jobs[job_schedule_type]))), jobs[salary_year_avg] ) )} -> 137300 | D11: Senior Data Scientist | E11: 160992 | F11: =IF($D11<>Title,E11,NA()) -> 160992 | G11: =IF($D11=Title,$E11,NA()) -> #N/A

Sheet Country
A1: job_country | B1: median_salary | D1: job_country_filter | G1: job_country_sorted
A2: {=_xlfn.ANCHORARRAY(Data_Validation!H2)} -> 0 | B2: {=MEDIAN( IF((jobs[job_country]=A2)* (jobs[salary_year_avg]<>0)*(jobs[job_title_short]=Title)*(ISNUMBER(SEARCH(Type,jobs[job_schedule_type]))), jobs[salary_year_avg]))} -> #NUM! | D2: {=_xlfn._xlws.FILTER(A2:B112,ISNUMBER(B2:B112))} -> Argentina | E2: 43199.5 | G2: {=_xlfn._xlws.SORT(_xlfn.ANCHORARRAY(D2),2,-1)} -> France | H2: 160500
A3: Afghanistan | B3: {=MEDIAN( IF((jobs[job_country]=A3)* (jobs[salary_year_avg]<>0)*(jobs[job_title_short]=Title)*(ISNUMBER(SEARCH(Type,jobs[job_schedule_type]))), jobs[salary_year_avg]))} -> #NUM! | D3: Australia | E3: 135000 | G3: Namibia | H3: 143500
A4: Albania | B4: {=MEDIAN( IF((jobs[job_country]=A4)* (jobs[salary_year_avg]<>0)*(jobs[job_title_short]=Title)*(ISNUMBER(SEARCH(Type,jobs[job_schedule_type]))), jobs[salary_year_avg]))} -> #NUM! | D4: Austria | E4: 70000 | G4: Australia | H4: 135000
A5: Algeria | B5: {=MEDIAN( IF((jobs[job_country]=A5)* (jobs[salary_year_avg]<>0)*(jobs[job_title_short]=Title)*(ISNUMBER(SEARCH(Type,jobs[job_schedule_type]))), jobs[salary_year_avg]))} -> #NUM! | D5: Azerbaijan | E5: 107517.5 | G5: New Zealand | H5: 122500
A6: Argentina | B6: {=MEDIAN( IF((jobs[job_country]=A6)* (jobs[salary_year_avg]<>0)*(jobs[job_title_short]=Title)*(ISNUMBER(SEARCH(Type,jobs[job_schedule_type]))), jobs[salary_year_avg]))} -> 43199.5 | D6: Bangladesh | E6: 72800 | G6: Mozambique | H6: 120163.5
A7: Armenia | B7: {=MEDIAN( IF((jobs[job_country]=A7)* (jobs[salary_year_avg]<>0)*(jobs[job_title_short]=Title)*(ISNUMBER(SEARCH(Type,jobs[job_schedule_type]))), jobs[salary_year_avg]))} -> #NUM! | D7: Benin | E7: 36900 | G7: Honduras | H7: 115000
A8: Australia | B8: {=MEDIAN( IF((jobs[job_country]=A8)* (jobs[salary_year_avg]<>0)*(jobs[job_title_short]=Title)*(ISNUMBER(SEARCH(Type,jobs[job_schedule_type]))), jobs[salary_year_avg]))} -> 135000 | D8: Canada | E8: 71500 | G8: Azerbaijan | H8: 107517.5
A9: Austria | B9: {=MEDIAN( IF((jobs[job_country]=A9)* (jobs[salary_year_avg]<>0)*(jobs[job_title_short]=Title)*(ISNUMBER(SEARCH(Type,jobs[job_schedule_type]))), jobs[salary_year_avg]))} -> 70000 | D9: Chile | E9: 37499.5 | G9: Mongolia | H9: 100000
A10: Azerbaijan | B10: {=MEDIAN( IF((jobs[job_country]=A10)* (jobs[salary_year_avg]<>0)*(jobs[job_title_short]=Title)*(ISNUMBER(SEARCH(Type,jobs[job_schedule_type]))), jobs[salary_year_avg]))} -> 107517.5 | D10: Colombia | E10: 37499.5 | G10: Panama | H10: 97000
A11: Bahamas | B11: {=MEDIAN( IF((jobs[job_country]=A11)* (jobs[salary_year_avg]<>0)*(jobs[job_title_short]=Title)*(ISNUMBER(SEARCH(Type,jobs[job_schedule_type]))), jobs[salary_year_avg]))} -> #NUM! | D11: Congo, Democratic Republic of the | E11: 40000 | G11: Mexico | H11: 95040
A12: Bahrain | B12: {=MEDIAN( IF((jobs[job_country]=A12)* (jobs[salary_year_avg]<>0)*(jobs[job_title_short]=Title)*(ISNUMBER(SEARCH(Type,jobs[job_schedule_type]))), jobs[salary_year_avg]))} -> #NUM! | D12: Costa Rica | E12: 91959.5 | G12: Cyprus | H12: 94250
A13: Bangladesh | B13: {=MEDIAN( IF((jobs[job_country]=A13)* (jobs[salary_year_avg]<>0)*(jobs[job_title_short]=Title)*(ISNUMBER(SEARCH(Type,jobs[job_schedule_type]))), jobs[salary_year_avg]))} -> 72800 | D13: Cyprus | E13: 94250 | G13: Costa Rica | H13: 91959.5
A14: Barbados | B14: {=MEDIAN( IF((jobs[job_country]=A14)* (jobs[salary_year_avg]<>0)*(jobs[job_title_short]=Title)*(ISNUMBER(SEARCH(Type,jobs[job_schedule_type]))), jobs[salary_year_avg]))} -> #NUM! | D14: Czechia | E14: 40000 | G14: Netherlands | H14: 90600
... A48: Hong Kong | B48: {=MEDIAN( IF((jobs[job_country]=A48)* (jobs[salary_year_avg]<>0)*(jobs[job_title_short]=Title)*(ISNUMBER(SEARCH(Type,jobs[job_schedule_type]))), jobs[salary_year_avg]))} -> 53560 | D48: South Korea | E48: 85000 | G48: Lesotho | H48: 32000
A49: Hungary | B49: {=MEDIAN( IF((jobs[job_country]=A49)* (jobs[salary_year_avg]<>0)*(jobs[job_title_short]=Title)*(ISNUMBER(SEARCH(Type,jobs[job_schedule_type]))), jobs[salary_year_avg]))} -> 55000
A50: Iceland | B50: {=MEDIAN( IF((jobs[job_country]=A50)* (jobs[salary_year_avg]<>0)*(jobs[job_title_short]=Title)*(ISNUMBER(SEARCH(Type,jobs[job_schedule_type]))), jobs[salary_year_avg]))} -> #NUM!
A51: India | B51: {=MEDIAN( IF((jobs[job_country]=A51)* (jobs[salary_year_avg]<>0)*(jobs[job_title_short]=Title)*(ISNUMBER(SEARCH(Type,jobs[job_schedule_type]))), jobs[salary_year_avg]))} -> 43156
A52: Indonesia | B52: {=MEDIAN( IF((jobs[job_country]=A52)* (jobs[salary_year_avg]<>0)*(jobs[job_title_short]=Title)*(ISNUMBER(SEARCH(Type,jobs[job_schedule_type]))), jobs[salary_year_avg]))} -> 38415.75
A53: Ireland | B53: {=MEDIAN( IF((jobs[job_country]=A53)* (jobs[salary_year_avg]<>0)*(jobs[job_title_short]=Title)*(ISNUMBER(SEARCH(Type,jobs[job_schedule_type]))), jobs[salary_year_avg]))} -> #NUM!
A54: Israel | B54: {=MEDIAN( IF((jobs[job_country]=A54)* (jobs[salary_year_avg]<>0)*(jobs[job_title_short]=Title)*(ISNUMBER(SEARCH(Type,jobs[job_schedule_type]))), jobs[salary_year_avg]))} -> 41600
A55: Italy | B55: {=MEDIAN( IF((jobs[job_country]=A55)* (jobs[salary_year_avg]<>0)*(jobs[job_title_short]=Title)*(ISNUMBER(SEARCH(Type,jobs[job_schedule_type]))), jobs[salary_year_avg]))} -> #NUM!
A56: Jamaica | B56: {=MEDIAN( IF((jobs[job_country]=A56)* (jobs[salary_year_avg]<>0)*(jobs[job_title_short]=Title)*(ISNUMBER(SEARCH(Type,jobs[job_schedule_type]))), jobs[salary_year_avg]))} -> #NUM!
A57: Japan | B57: {=MEDIAN( IF((jobs[job_country]=A57)* (jobs[salary_year_avg]<>0)*(jobs[job_title_short]=Title)*(ISNUMBER(SEARCH(Type,jobs[job_schedule_type]))), jobs[salary_year_avg]))} -> #NUM!
A58: Jordan | B58: {=MEDIAN( IF((jobs[job_country]=A58)* (jobs[salary_year_avg]<>0)*(jobs[job_title_short]=Title)*(ISNUMBER(SEARCH(Type,jobs[job_schedule_type]))), jobs[salary_year_avg]))} -> #NUM!
A59: Kazakhstan | B59: {=MEDIAN( IF((jobs[job_country]=A59)* (jobs[salary_year_avg]<>0)*(jobs[job_title_short]=Title)*(ISNUMBER(SEARCH(Type,jobs[job_schedule_type]))), jobs[salary_year_avg]))} -> 85600
A60: Kenya | B60: {=MEDIAN( IF((jobs[job_country]=A60)* (jobs[salary_year_avg]<>0)*(jobs[job_title_short]=Title)*(ISNUMBER(SEARCH(Type,jobs[job_schedule_type]))), jobs[salary_year_avg]))} -> 63459.5
... A112: South Korea | B112: {=MEDIAN( IF((jobs[job_country]=A112)* (jobs[salary_year_avg]<>0)*(jobs[job_title_short]=Title)*(ISNUMBER(SEARCH(Type,jobs[job_schedule_type]))), jobs[salary_year_avg]))} -> 85000
A113: Spain
A114: Sri Lanka
A115: Sudan
A116: Suriname
A117: Switzerland
A118: Taiwan
A119: Tanzania
A120: Thailand
A121: Trinidad and Tobago
A122: Tunisia
A123: Turkey
A124: U.S. Virgin Islands
...

Sheet Type
A1: job_schedule_type_sorted
A2: =Data_Validation!K2 -> Full-time | B2: {=MEDIAN( IF( (jobs[job_title_short]=Title)* (jobs[salary_year_avg]<>0)* (jobs[job_country]= Country)* (ISNUMBER(SEARCH(A2,jobs[job_schedule_type]))), jobs[salary_year_avg] ) )} -> 93580 | D2: {=_xlfn._xlws.SORT(_xlfn._xlws.FILTER(A2:B6,ISNUMBER(B2:B6)),2,1)} -> Contractor | E2: 76212 | F2: =IF($D2<>Type,$E2,NA()) -> 76212 | G2: =IF($D2=Type,$E2,NA()) -> #N/A
A3: =Data_Validation!K3 -> Contractor | B3: {=MEDIAN( IF( (jobs[job_title_short]=Title)* (jobs[salary_year_avg]<>0)* (jobs[job_country]= Country)* (ISNUMBER(SEARCH(A3,jobs[job_schedule_type]))), jobs[salary_year_avg] ) )} -> 76212 | D3: Part-time | E3: 80774.5 | F3: =IF($D3<>Type,$E3,NA()) -> 80774.5 | G3: =IF($D3=Type,$E3,NA()) -> #N/A
A4: =Data_Validation!K4 -> Part-time | B4: {=MEDIAN( IF( (jobs[job_title_short]=Title)* (jobs[salary_year_avg]<>0)* (jobs[job_country]= Country)* (ISNUMBER(SEARCH(A4,jobs[job_schedule_type]))), jobs[salary_year_avg] ) )} -> 80774.5 | D4: Internship | E4: 87500 | F4: =IF($D4<>Type,$E4,NA()) -> 87500 | G4: =IF($D4=Type,$E4,NA()) -> #N/A
A5: =Data_Validation!K5 -> Internship | B5: {=MEDIAN( IF( (jobs[job_title_short]=Title)* (jobs[salary_year_avg]<>0)* (jobs[job_country]= Country)* (ISNUMBER(SEARCH(A5,jobs[job_schedule_type]))), jobs[salary_year_avg] ) )} -> 87500 | D5: Full-time | E5: 93580 | F5: =IF($D5<>Type,$E5,NA()) -> #N/A | G5: =IF($D5=Type,$E5,NA()) -> 93580
A6: =Data_Validation!K6 -> 0 | B6: {=MEDIAN( IF( (jobs[job_title_short]=Title)* (jobs[salary_year_avg]<>0)* (jobs[job_country]= Country)* (ISNUMBER(SEARCH(A6,jobs[job_schedule_type]))), jobs[salary_year_avg] ) )} -> #NUM! | F6: =IF($D6<>Type,$E6,NA()) -> 0 | G6: =IF($D6=Type,$E6,NA()) -> #N/A

Sheet Plataform
A1: job_via | B1: via_count
A2: {=_xlfn.UNIQUE(jobs[job_via])} -> Snagajob | B2: =COUNTIFS(jobs[job_via],A2,jobs[job_title_short],Title,jobs[job_country],Country,jobs[job_schedule_type],Type) -> 227 | D2: {=_xlfn._xlws.SORT(A2:B594,2,-1)} -> LinkedIn | E2: 705 | G2: =SUBSTITUTE(D2,"via","") -> LinkedIn
A3: JobLeads | B3: =COUNTIFS(jobs[job_via],A3,jobs[job_title_short],Title,jobs[job_country],Country,jobs[job_schedule_type],Type) -> 0 | D3: Indeed | E3: 533
A4: Ladders | B4: =COUNTIFS(jobs[job_via],A4,jobs[job_title_short],Title,jobs[job_country],Country,jobs[job_schedule_type],Type) -> 33 | D4: ZipRecruiter | E4: 279
A5: LinkedIn | B5: =COUNTIFS(jobs[job_via],A5,jobs[job_title_short],Title,jobs[job_country],Country,jobs[job_schedule_type],Type) -> 705 | D5: Snagajob | E5: 227
A6: ZipRecruiter | B6: =COUNTIFS(jobs[job_via],A6,jobs[job_title_short],Title,jobs[job_country],Country,jobs[job_schedule_type],Type) -> 279 | D6: BeBee | E6: 191
A7: JobzMall | B7: =COUNTIFS(jobs[job_via],A7,jobs[job_title_short],Title,jobs[job_country],Country,jobs[job_schedule_type],Type) -> 0 | D7: Adzuna | E7: 43
A8: Jobgether | B8: =COUNTIFS(jobs[job_via],A8,jobs[job_title_short],Title,jobs[job_country],Country,jobs[job_schedule_type],Type) -> 5 | D8: Dice | E8: 42
A9: Rise | B9: =COUNTIFS(jobs[job_via],A9,jobs[job_title_short],Title,jobs[job_country],Country,jobs[job_schedule_type],Type) -> 0 | D9: Dice.com | E9: 39
A10: Taro | B10: =COUNTIFS(jobs[job_via],A10,jobs[job_title_short],Title,jobs[job_country],Country,jobs[job_schedule_type],Type) -> 1 | D10: Ladders | E10: 33
A11: LinkedIn Tanzania | B11: =COUNTIFS(jobs[job_via],A11,jobs[job_title_short],Title,jobs[job_country],Country,jobs[job_schedule_type],Type) -> 0 | D11: Built In NYC | E11: 23
A12: Built In | B12: =COUNTIFS(jobs[job_via],A12,jobs[job_title_short],Title,jobs[job_country],Country,jobs[job_schedule_type],Type) -> 22 | D12: Built In | E12: 22
A13: LinkedIn El Salvador | B13: =COUNTIFS(jobs[job_via],A13,jobs[job_title_short],Title,jobs[job_country],Country,jobs[job_schedule_type],Type) -> 0 | D13: Trabajo.org | E13: 22
A14: LinkedIn Cameroon | B14: =COUNTIFS(jobs[job_via],A14,jobs[job_title_short],Title,jobs[job_country],Country,jobs[job_schedule_type],Type) -> 0 | D14: Aston Carter | E14: 22
... A343: BeBee KW | B343: =COUNTIFS(jobs[job_via],A343,jobs[job_title_short],Title,jobs[job_country],Country,jobs[job_schedule_type],Type) -> 0 | D343: BeBee KW | E343: 0
A344: 0 | B344: =COUNTIFS(jobs[job_via],A344,jobs[job_title_short],Title,jobs[job_country],Country,jobs[job_schedule_type],Type) -> 0 | D344: 0 | E344: 0
B345: =COUNTIFS(jobs[job_via],A345,jobs[job_title_short],Title,jobs[job_country],Country,jobs[job_schedule_type],Type) -> 0 | D345: 0 | E345: 0
B346: =COUNTIFS(jobs[job_via],A346,jobs[job_title_short],Title,jobs[job_country],Country,jobs[job_schedule_type],Type) -> 0 | D346: 0 | E346: 0
B347: =COUNTIFS(jobs[job_via],A347,jobs[job_title_short],Title,jobs[job_country],Country,jobs[job_schedule_type],Type) -> 0 | D347: 0 | E347: 0
B348: =COUNTIFS(jobs[job_via],A348,jobs[job_title_short],Title,jobs[job_country],Country,jobs[job_schedule_type],Type) -> 0 | D348: 0 | E348: 0
B349: =COUNTIFS(jobs[job_via],A349,jobs[job_title_short],Title,jobs[job_country],Country,jobs[job_schedule_type],Type) -> 0 | D349: 0 | E349: 0
B350: =COUNTIFS(jobs[job_via],A350,jobs[job_title_short],Title,jobs[job_country],Country,jobs[job_schedule_type],Type) -> 0 | D350: 0 | E350: 0
B351: =COUNTIFS(jobs[job_via],A351,jobs[job_title_short],Title,jobs[job_country],Country,jobs[job_schedule_type],Type) -> 0 | D351: 0 | E351: 0
B352: =COUNTIFS(jobs[job_via],A352,jobs[job_title_short],Title,jobs[job_country],Country,jobs[job_schedule_type],Type) -> 0 | D352: 0 | E352: 0
B353: =COUNTIFS(jobs[job_via],A353,jobs[job_title_short],Title,jobs[job_country],Country,jobs[job_schedule_type],Type) -> 0 | D353: 0 | E353: 0
B354: =COUNTIFS(jobs[job_via],A354,jobs[job_title_short],Title,jobs[job_country],Country,jobs[job_schedule_type],Type) -> 0 | D354: 0 | E354: 0
B355: =COUNTIFS(jobs[job_via],A355,jobs[job_title_short],Title,jobs[job_country],Country,jobs[job_schedule_type],Type) -> 0 | D355: 0 | E355: 0
B356: =COUNTIFS(jobs[job_via],A356,jobs[job_title_short],Title,jobs[job_country],Country,jobs[job_schedule_type],Type) -> 0 | D356: 0 | E356: 0
... B594: =COUNTIFS(jobs[job_via],A594,jobs[job_title_short],Title,jobs[job_country],Country,jobs[job_schedule_type],Type) -> 0 | D594: 0 | E594: 0
